{"url": "https://api.github.com/repos/datalad/datalad/issues/255", "repository_url": "https://api.github.com/repos/datalad/datalad", "labels_url": "https://api.github.com/repos/datalad/datalad/issues/255/labels{/name}", "comments_url": "https://api.github.com/repos/datalad/datalad/issues/255/comments", "events_url": "https://api.github.com/repos/datalad/datalad/issues/255/events", "html_url": "https://github.com/datalad/datalad/issues/255", "id": 109825717, "node_id": "MDU6SXNzdWUxMDk4MjU3MTc=", "number": 255, "title": "Strange failure on test_install_handle_basic", "user": {"login": "bpoldrack", "id": 10498301, "node_id": "MDQ6VXNlcjEwNDk4MzAx", "avatar_url": "https://avatars.githubusercontent.com/u/10498301?v=4", "gravatar_id": "", "url": "https://api.github.com/users/bpoldrack", "html_url": "https://github.com/bpoldrack", "followers_url": "https://api.github.com/users/bpoldrack/followers", "following_url": "https://api.github.com/users/bpoldrack/following{/other_user}", "gists_url": "https://api.github.com/users/bpoldrack/gists{/gist_id}", "starred_url": "https://api.github.com/users/bpoldrack/starred{/owner}{/repo}", "subscriptions_url": "https://api.github.com/users/bpoldrack/subscriptions", "organizations_url": "https://api.github.com/users/bpoldrack/orgs", "repos_url": "https://api.github.com/users/bpoldrack/repos", "events_url": "https://api.github.com/users/bpoldrack/events{/privacy}", "received_events_url": "https://api.github.com/users/bpoldrack/received_events", "type": "User", "site_admin": false}, "labels": [], "state": "closed", "locked": false, "assignee": null, "assignees": [], "milestone": null, "comments": 2, "created_at": "2015-10-05T15:42:14Z", "updated_at": "2015-10-07T07:50:40Z", "closed_at": "2015-10-07T07:50:40Z", "author_association": "MEMBER", "active_lock_reason": null, "body": "I'm currently experiencing something strange.\nThat test fails due to the try to create an import branch that is already existing, when installing a handle a second time.\nBut, this test is sometimes failing and sometimes it isn't. Even if I call it directly via nosetests:\n\n```\nnosetests -s -v datalad.interface.tests.test_install_handle:test_install_handle_basic\n```\n\nIt first fails, but when repeating it several times, it sometimes doesn't fail in between. Sometimes it passes on python2 but fails on python3, sometimes and fails both times. Calling the to be tested command directly works for me. Any ideas?\n", "closed_by": {"login": "bpoldrack", "id": 10498301, "node_id": "MDQ6VXNlcjEwNDk4MzAx", "avatar_url": "https://avatars.githubusercontent.com/u/10498301?v=4", "gravatar_id": "", "url": "https://api.github.com/users/bpoldrack", "html_url": "https://github.com/bpoldrack", "followers_url": "https://api.github.com/users/bpoldrack/followers", "following_url": "https://api.github.com/users/bpoldrack/following{/other_user}", "gists_url": "https://api.github.com/users/bpoldrack/gists{/gist_id}", "starred_url": "https://api.github.com/users/bpoldrack/starred{/owner}{/repo}", "subscriptions_url": "https://api.github.com/users/bpoldrack/subscriptions", "organizations_url": "https://api.github.com/users/bpoldrack/orgs", "repos_url": "https://api.github.com/users/bpoldrack/repos", "events_url": "https://api.github.com/users/bpoldrack/events{/privacy}", "received_events_url": "https://api.github.com/users/bpoldrack/received_events", "type": "User", "site_admin": false}, "reactions": {"url": "https://api.github.com/repos/datalad/datalad/issues/255/reactions", "total_count": 0, "+1": 0, "-1": 0, "laugh": 0, "hooray": 0, "confused": 0, "heart": 0, "rocket": 0, "eyes": 0}, "timeline_url": "https://api.github.com/repos/datalad/datalad/issues/255/timeline", "performed_via_github_app": null}