{"url": "https://api.github.com/repos/datalad/datalad/issues/3217", "repository_url": "https://api.github.com/repos/datalad/datalad", "labels_url": "https://api.github.com/repos/datalad/datalad/issues/3217/labels{/name}", "comments_url": "https://api.github.com/repos/datalad/datalad/issues/3217/comments", "events_url": "https://api.github.com/repos/datalad/datalad/issues/3217/events", "html_url": "https://github.com/datalad/datalad/issues/3217", "id": 419543039, "node_id": "MDU6SXNzdWU0MTk1NDMwMzk=", "number": 3217, "title": "Travis: Crawler run failing in master (related to direct mode)", "user": {"login": "kyleam", "id": 1297788, "node_id": "MDQ6VXNlcjEyOTc3ODg=", "avatar_url": "https://avatars.githubusercontent.com/u/1297788?v=4", "gravatar_id": "", "url": "https://api.github.com/users/kyleam", "html_url": "https://github.com/kyleam", "followers_url": "https://api.github.com/users/kyleam/followers", "following_url": "https://api.github.com/users/kyleam/following{/other_user}", "gists_url": "https://api.github.com/users/kyleam/gists{/gist_id}", "starred_url": "https://api.github.com/users/kyleam/starred{/owner}{/repo}", "subscriptions_url": "https://api.github.com/users/kyleam/subscriptions", "organizations_url": "https://api.github.com/users/kyleam/orgs", "repos_url": "https://api.github.com/users/kyleam/repos", "events_url": "https://api.github.com/users/kyleam/events{/privacy}", "received_events_url": "https://api.github.com/users/kyleam/received_events", "type": "User", "site_admin": false}, "labels": [], "state": "closed", "locked": false, "assignee": null, "assignees": [], "milestone": null, "comments": 3, "created_at": "2019-03-11T15:47:56Z", "updated_at": "2019-03-15T20:13:08Z", "closed_at": "2019-03-15T20:13:08Z", "author_association": "MEMBER", "active_lock_reason": null, "body": "Until a02e6da88 (TST: travis: Widen selector for extension runs, 2019-03-08), our crawler Travis run only executed a small subset of the tests.  Now that this is brought into master, a crawler test fails (below) because master has dropped direct mode.  I'm opening this issue here because the failure is happening in core, but I think the main fix would have to happen on crawler's side.\r\n\r\n<details>\r\n<summary>Crawler failures</summary>\r\n\r\nhttps://travis-ci.org/datalad/datalad/jobs/504695887\r\n\r\n```\r\n======================================================================\r\nERROR: datalad_crawler.nodes.tests.test_annex.test_add_archive_content_tar(True,)\r\n----------------------------------------------------------------------\r\nTraceback (most recent call last):\r\n  File \"/home/travis/virtualenv/python3.5.6/lib/python3.5/site-packages/nose/case.py\", line 198, in runTest\r\n    self.test(*self.arg)\r\n  File \"/home/travis/virtualenv/python3.5.6/lib/python3.5/site-packages/datalad/tests/utils.py\", line 1112, in newfunc\r\n    reraise(*exc_info)\r\n  File \"/home/travis/virtualenv/python3.5.6/lib/python3.5/site-packages/six.py\", line 693, in reraise\r\n    raise value\r\n  File \"/home/travis/virtualenv/python3.5.6/lib/python3.5/site-packages/datalad/tests/utils.py\", line 1084, in newfunc\r\n    ret = func(*args, **kwargs)\r\n  File \"/home/travis/virtualenv/python3.5.6/lib/python3.5/site-packages/datalad/tests/utils.py\", line 431, in newfunc\r\n    return t(*(arg + (d,)), **kw)\r\n  File \"/home/travis/virtualenv/python3.5.6/lib/python3.5/site-packages/datalad_crawler/nodes/tests/test_annex.py\", line 193, in _test_add_archive_content_tar\r\n    largefiles=\"exclude=*.txt and exclude=SOMEOTHER\")\r\n  File \"/home/travis/virtualenv/python3.5.6/lib/python3.5/site-packages/datalad_crawler/nodes/annex.py\", line 300, in __init__\r\n    self.repo = (GitRepo if no_annex else AnnexRepo)(path, always_commit=False, **kwargs)\r\n  File \"/home/travis/virtualenv/python3.5.6/lib/python3.5/site-packages/datalad/support/repo.py\", line 146, in __call__\r\n    instance = type.__call__(cls, *new_args, **new_kwargs)\r\nTypeError: __init__() got an unexpected keyword argument 'direct'\r\n======================================================================\r\nERROR: datalad_crawler.nodes.tests.test_annex.test_add_archive_content_tar(False,)\r\n----------------------------------------------------------------------\r\nTraceback (most recent call last):\r\n  File \"/home/travis/virtualenv/python3.5.6/lib/python3.5/site-packages/nose/case.py\", line 198, in runTest\r\n    self.test(*self.arg)\r\n  File \"/home/travis/virtualenv/python3.5.6/lib/python3.5/site-packages/datalad/tests/utils.py\", line 1112, in newfunc\r\n    reraise(*exc_info)\r\n  File \"/home/travis/virtualenv/python3.5.6/lib/python3.5/site-packages/six.py\", line 693, in reraise\r\n    raise value\r\n  File \"/home/travis/virtualenv/python3.5.6/lib/python3.5/site-packages/datalad/tests/utils.py\", line 1084, in newfunc\r\n    ret = func(*args, **kwargs)\r\n  File \"/home/travis/virtualenv/python3.5.6/lib/python3.5/site-packages/datalad/tests/utils.py\", line 431, in newfunc\r\n    return t(*(arg + (d,)), **kw)\r\n  File \"/home/travis/virtualenv/python3.5.6/lib/python3.5/site-packages/datalad_crawler/nodes/tests/test_annex.py\", line 193, in _test_add_archive_content_tar\r\n    largefiles=\"exclude=*.txt and exclude=SOMEOTHER\")\r\n  File \"/home/travis/virtualenv/python3.5.6/lib/python3.5/site-packages/datalad_crawler/nodes/annex.py\", line 300, in __init__\r\n    self.repo = (GitRepo if no_annex else AnnexRepo)(path, always_commit=False, **kwargs)\r\n  File \"/home/travis/virtualenv/python3.5.6/lib/python3.5/site-packages/datalad/support/repo.py\", line 146, in __call__\r\n    instance = type.__call__(cls, *new_args, **new_kwargs)\r\nTypeError: __init__() got an unexpected keyword argument 'direct'\r\n\r\n```\r\n\r\n</details>\r\n\r\n", "closed_by": {"login": "yarikoptic", "id": 39889, "node_id": "MDQ6VXNlcjM5ODg5", "avatar_url": "https://avatars.githubusercontent.com/u/39889?v=4", "gravatar_id": "", "url": "https://api.github.com/users/yarikoptic", "html_url": "https://github.com/yarikoptic", "followers_url": "https://api.github.com/users/yarikoptic/followers", "following_url": "https://api.github.com/users/yarikoptic/following{/other_user}", "gists_url": "https://api.github.com/users/yarikoptic/gists{/gist_id}", "starred_url": "https://api.github.com/users/yarikoptic/starred{/owner}{/repo}", "subscriptions_url": "https://api.github.com/users/yarikoptic/subscriptions", "organizations_url": "https://api.github.com/users/yarikoptic/orgs", "repos_url": "https://api.github.com/users/yarikoptic/repos", "events_url": "https://api.github.com/users/yarikoptic/events{/privacy}", "received_events_url": "https://api.github.com/users/yarikoptic/received_events", "type": "User", "site_admin": false}, "reactions": {"url": "https://api.github.com/repos/datalad/datalad/issues/3217/reactions", "total_count": 0, "+1": 0, "-1": 0, "laugh": 0, "hooray": 0, "confused": 0, "heart": 0, "rocket": 0, "eyes": 0}, "timeline_url": "https://api.github.com/repos/datalad/datalad/issues/3217/timeline", "performed_via_github_app": null}