{"url": "https://api.github.com/repos/datalad/datalad/issues/3633", "repository_url": "https://api.github.com/repos/datalad/datalad", "labels_url": "https://api.github.com/repos/datalad/datalad/issues/3633/labels{/name}", "comments_url": "https://api.github.com/repos/datalad/datalad/issues/3633/comments", "events_url": "https://api.github.com/repos/datalad/datalad/issues/3633/events", "html_url": "https://github.com/datalad/datalad/issues/3633", "id": 487748012, "node_id": "MDU6SXNzdWU0ODc3NDgwMTI=", "number": 3633, "title": "datalad.core test failures on real win10/conda", "user": {"login": "mih", "id": 136479, "node_id": "MDQ6VXNlcjEzNjQ3OQ==", "avatar_url": "https://avatars.githubusercontent.com/u/136479?v=4", "gravatar_id": "", "url": "https://api.github.com/users/mih", "html_url": "https://github.com/mih", "followers_url": "https://api.github.com/users/mih/followers", "following_url": "https://api.github.com/users/mih/following{/other_user}", "gists_url": "https://api.github.com/users/mih/gists{/gist_id}", "starred_url": "https://api.github.com/users/mih/starred{/owner}{/repo}", "subscriptions_url": "https://api.github.com/users/mih/subscriptions", "organizations_url": "https://api.github.com/users/mih/orgs", "repos_url": "https://api.github.com/users/mih/repos", "events_url": "https://api.github.com/users/mih/events{/privacy}", "received_events_url": "https://api.github.com/users/mih/received_events", "type": "User", "site_admin": false}, "labels": [{"id": 188141023, "node_id": "MDU6TGFiZWwxODgxNDEwMjM=", "url": "https://api.github.com/repos/datalad/datalad/labels/platform-windows", "name": "platform-windows", "color": "0052cc", "default": false, "description": "Issue concerned with Windows"}], "state": "closed", "locked": false, "assignee": null, "assignees": [], "milestone": null, "comments": 1, "created_at": "2019-08-31T08:51:23Z", "updated_at": "2020-01-01T12:41:23Z", "closed_at": "2020-01-01T12:41:23Z", "author_association": "MEMBER", "active_lock_reason": null, "body": "The appveyor environment is supercharged in many ways. Here is a glimpse of reality starting from https://github.com/datalad-handbook/book/issues/132:\r\n\r\n```\r\n> python -m nose datalad.core\r\n======================================================================\r\nERROR: datalad.core.local.tests.test_create.test_create_with_obscure_name({'path': ' ;abc\u0394\u0419\u05e7\u0645\u0e57 \u3042'},)\r\n----------------------------------------------------------------------\r\nTraceback (most recent call last):\r\n  File \"C:\\Users\\mih\\Miniconda3\\lib\\site-packages\\nose\\case.py\", line 198, in runTest\r\n    self.test(*self.arg)\r\n  File \"c:\\users\\mih\\code\\datalad\\datalad\\tests\\utils.py\", line 607, in newfunc\r\n    return t(*(arg + (filename,)), **kw)\r\n  File \"c:\\users\\mih\\code\\datalad\\datalad\\core\\local\\tests\\test_create.py\", line 470, in check_create_obscure\r\n    ds = create(result_renderer=\"default\", **create_kwargs)\r\n  File \"C:\\Users\\mih\\Miniconda3\\lib\\site-packages\\wrapt\\wrappers.py\", line 564, in __call__\r\n    args, kwargs)\r\n  File \"c:\\users\\mih\\code\\datalad\\datalad\\interface\\utils.py\", line 499, in eval_func\r\n    return return_func(generator_func)(*args, **kwargs)\r\n  File \"C:\\Users\\mih\\Miniconda3\\lib\\site-packages\\wrapt\\wrappers.py\", line 564, in __call__\r\n    args, kwargs)\r\n  File \"c:\\users\\mih\\code\\datalad\\datalad\\interface\\utils.py\", line 487, in return_func\r\n    results = list(results)\r\n  File \"c:\\users\\mih\\code\\datalad\\datalad\\interface\\utils.py\", line 435, in generator_func\r\n    result_renderer, result_xfm, _result_filter, **_kwargs):\r\n  File \"c:\\users\\mih\\code\\datalad\\datalad\\interface\\utils.py\", line 595, in _process_results\r\n    default_result_renderer(res)\r\n  File \"c:\\users\\mih\\code\\datalad\\datalad\\interface\\utils.py\", line 526, in default_result_renderer\r\n    if 'message' in res else ''))\r\n  File \"c:\\users\\mih\\code\\datalad\\datalad\\ui\\dialog.py\", line 75, in message\r\n    self.out.write(msg)\r\n  File \"C:\\Users\\mih\\Miniconda3\\lib\\encodings\\cp1252.py\", line 19, in encode\r\n    return codecs.charmap_encode(input,self.errors,encoding_table)[0]\r\nUnicodeEncodeError: 'charmap' codec can't encode characters in position 71-76: character maps to <undefined>\r\n\r\n======================================================================\r\nERROR: datalad.core.local.tests.test_diff.test_path_diff\r\n----------------------------------------------------------------------\r\nTraceback (most recent call last):\r\n  File \"C:\\Users\\mih\\Miniconda3\\lib\\site-packages\\nose\\case.py\", line 198, in runTest\r\n    self.test(*self.arg)\r\n  File \"c:\\users\\mih\\code\\datalad\\datalad\\tests\\utils.py\", line 607, in newfunc\r\n    return t(*(arg + (filename,)), **kw)\r\n  File \"c:\\users\\mih\\code\\datalad\\datalad\\tests\\utils.py\", line 607, in newfunc\r\n    return t(*(arg + (filename,)), **kw)\r\n  File \"c:\\users\\mih\\code\\datalad\\datalad\\core\\local\\tests\\test_diff.py\", line 305, in test_path_diff\r\n    ds = get_deeply_nested_structure(str(_path))\r\n  File \"c:\\users\\mih\\code\\datalad\\datalad\\tests\\utils.py\", line 1754, in get_deeply_nested_structure\r\n    'annexed_file.txt')\r\n  File \"C:\\Users\\mih\\Miniconda3\\lib\\pathlib.py\", line 1330, in symlink_to\r\n    self._accessor.symlink(target, self, target_is_directory)\r\nOSError: symbolic link privilege not held\r\n\r\n======================================================================\r\nERROR: datalad.core.local.tests.test_run.test_py2_unicode_command\r\n----------------------------------------------------------------------\r\nTraceback (most recent call last):\r\n  File \"C:\\Users\\mih\\Miniconda3\\lib\\site-packages\\nose\\case.py\", line 198, in runTest\r\n    self.test(*self.arg)\r\n  File \"c:\\users\\mih\\code\\datalad\\datalad\\tests\\utils.py\", line 607, in newfunc\r\n    return t(*(arg + (filename,)), **kw)\r\n  File \"c:\\users\\mih\\code\\datalad\\datalad\\core\\local\\tests\\test_run.py\", line 149, in test_py2_unicode_command\r\n    ds.run(cmd_str)\r\n  File \"C:\\Users\\mih\\Miniconda3\\lib\\site-packages\\wrapt\\wrappers.py\", line 603, in __call__\r\n    args, kwargs)\r\n  File \"c:\\users\\mih\\code\\datalad\\datalad\\distribution\\dataset.py\", line 526, in apply_func\r\n    return f(**kwargs)\r\n  File \"C:\\Users\\mih\\Miniconda3\\lib\\site-packages\\wrapt\\wrappers.py\", line 564, in __call__\r\n    args, kwargs)\r\n  File \"c:\\users\\mih\\code\\datalad\\datalad\\interface\\utils.py\", line 499, in eval_func\r\n    return return_func(generator_func)(*args, **kwargs)\r\n  File \"C:\\Users\\mih\\Miniconda3\\lib\\site-packages\\wrapt\\wrappers.py\", line 564, in __call__\r\n    args, kwargs)\r\n  File \"c:\\users\\mih\\code\\datalad\\datalad\\interface\\utils.py\", line 487, in return_func\r\n    results = list(results)\r\n  File \"c:\\users\\mih\\code\\datalad\\datalad\\interface\\utils.py\", line 435, in generator_func\r\n    result_renderer, result_xfm, _result_filter, **_kwargs):\r\n  File \"c:\\users\\mih\\code\\datalad\\datalad\\interface\\utils.py\", line 536, in _process_results\r\n    for res in results:\r\n  File \"c:\\users\\mih\\code\\datalad\\datalad\\core\\local\\run.py\", line 203, in __call__\r\n    sidecar=sidecar):\r\n  File \"c:\\users\\mih\\code\\datalad\\datalad\\core\\local\\run.py\", line 648, in run_command\r\n    for r in saver(ds, outputs_to_save, msg):\r\n  File \"c:\\users\\mih\\code\\datalad\\datalad\\interface\\utils.py\", line 474, in generator_func\r\n    msg=\"Command did not complete successfully\")\r\ndatalad.support.exceptions.IncompleteResultsError: Command did not complete successfully [{'action': 'add', 'path': 'C:\\\\Users\\\\mih\\\\AppData\\\\Local\\\\Temp\\\\datalad_temp_nzuxpxpy\\\\b\u03b20.dat', 'type': 'file', 'refds': 'C:\\\\Users\\\\mih\\\\AppData\\\\Local\\\\Temp\\\\datalad_temp_nzuxpxpy', 'status': 'error', 'key': None}]\r\n\r\n======================================================================\r\nERROR: datalad.core.local.tests.test_save.test_add_files\r\n----------------------------------------------------------------------\r\nTraceback (most recent call last):\r\n  File \"C:\\Users\\mih\\Miniconda3\\lib\\site-packages\\nose\\case.py\", line 198, in runTest\r\n    self.test(*self.arg)\r\n  File \"c:\\users\\mih\\code\\datalad\\datalad\\tests\\utils.py\", line 434, in newfunc\r\n    return t(*(arg + (d,)), **kw)\r\n  File \"c:\\users\\mih\\code\\datalad\\datalad\\core\\local\\tests\\test_save.py\", line 358, in test_add_files\r\n    result = ds.save('dir', to_git=arg[1])\r\n  File \"C:\\Users\\mih\\Miniconda3\\lib\\site-packages\\wrapt\\wrappers.py\", line 603, in __call__\r\n    args, kwargs)\r\n  File \"c:\\users\\mih\\code\\datalad\\datalad\\distribution\\dataset.py\", line 526, in apply_func\r\n    return f(**kwargs)\r\n  File \"C:\\Users\\mih\\Miniconda3\\lib\\site-packages\\wrapt\\wrappers.py\", line 564, in __call__\r\n    args, kwargs)\r\n  File \"c:\\users\\mih\\code\\datalad\\datalad\\interface\\utils.py\", line 499, in eval_func\r\n    return return_func(generator_func)(*args, **kwargs)\r\n  File \"C:\\Users\\mih\\Miniconda3\\lib\\site-packages\\wrapt\\wrappers.py\", line 564, in __call__\r\n    args, kwargs)\r\n  File \"c:\\users\\mih\\code\\datalad\\datalad\\interface\\utils.py\", line 487, in return_func\r\n    results = list(results)\r\n  File \"c:\\users\\mih\\code\\datalad\\datalad\\interface\\utils.py\", line 474, in generator_func\r\n    msg=\"Command did not complete successfully\")\r\ndatalad.support.exceptions.IncompleteResultsError: Command did not complete successfully [{'action': 'add', 'path': 'C:\\\\Users\\\\mih\\\\AppData\\\\Local\\\\Temp\\\\datalad_temp_tree_ba7d91yb\\\\dir\\\\ ;abc\u0394\u0419\u05e7\u0645\u0e57\u3042', 'type': 'file', 'refds': 'C:\\\\Users\\\\mih\\\\AppData\\\\Local\\\\Temp\\\\datalad_temp_tree_ba7d91yb', 'status': 'error', 'key': None}]\r\n\r\n======================================================================\r\nERROR: datalad.core.local.tests.test_save.test_add_subdataset\r\n----------------------------------------------------------------------\r\nTraceback (most recent call last):\r\n  File \"C:\\Users\\mih\\Miniconda3\\lib\\site-packages\\nose\\case.py\", line 198, in runTest\r\n    self.test(*self.arg)\r\n  File \"c:\\users\\mih\\code\\datalad\\datalad\\tests\\utils.py\", line 434, in newfunc\r\n    return t(*(arg + (d,)), **kw)\r\n  File \"c:\\users\\mih\\code\\datalad\\datalad\\tests\\utils.py\", line 607, in newfunc\r\n    return t(*(arg + (filename,)), **kw)\r\n  File \"c:\\users\\mih\\code\\datalad\\datalad\\core\\local\\tests\\test_save.py\", line 382, in test_add_subdataset\r\n    save(dataset=subds.path)\r\n  File \"C:\\Users\\mih\\Miniconda3\\lib\\site-packages\\wrapt\\wrappers.py\", line 564, in __call__\r\n    args, kwargs)\r\n  File \"c:\\users\\mih\\code\\datalad\\datalad\\interface\\utils.py\", line 499, in eval_func\r\n    return return_func(generator_func)(*args, **kwargs)\r\n  File \"C:\\Users\\mih\\Miniconda3\\lib\\site-packages\\wrapt\\wrappers.py\", line 564, in __call__\r\n    args, kwargs)\r\n  File \"c:\\users\\mih\\code\\datalad\\datalad\\interface\\utils.py\", line 487, in return_func\r\n    results = list(results)\r\n  File \"c:\\users\\mih\\code\\datalad\\datalad\\interface\\utils.py\", line 474, in generator_func\r\n    msg=\"Command did not complete successfully\")\r\ndatalad.support.exceptions.IncompleteResultsError: Command did not complete successfully [{'action': 'add', 'path': 'C:\\\\Users\\\\mih\\\\AppData\\\\Local\\\\Temp\\\\datalad_temp_tree_5fx0ftm8\\\\dir\\\\ ;abc\u0394\u0419\u05e7\u0645\u0e57\u3042', 'type': 'file', 'refds': 'C:\\\\Users\\\\mih\\\\AppData\\\\Local\\\\Temp\\\\datalad_temp_tree_5fx0ftm8\\\\dir', 'status': 'error', 'key': None}]\r\n\r\n======================================================================\r\nERROR: datalad.core.local.tests.test_save.test_relpath_add\r\n----------------------------------------------------------------------\r\nTraceback (most recent call last):\r\n  File \"C:\\Users\\mih\\Miniconda3\\lib\\site-packages\\nose\\case.py\", line 198, in runTest\r\n    self.test(*self.arg)\r\n  File \"c:\\users\\mih\\code\\datalad\\datalad\\tests\\utils.py\", line 434, in newfunc\r\n    return t(*(arg + (d,)), **kw)\r\n  File \"c:\\users\\mih\\code\\datalad\\datalad\\core\\local\\tests\\test_save.py\", line 542, in test_relpath_add\r\n    save('..')\r\n  File \"C:\\Users\\mih\\Miniconda3\\lib\\site-packages\\wrapt\\wrappers.py\", line 564, in __call__\r\n    args, kwargs)\r\n  File \"c:\\users\\mih\\code\\datalad\\datalad\\interface\\utils.py\", line 499, in eval_func\r\n    return return_func(generator_func)(*args, **kwargs)\r\n  File \"C:\\Users\\mih\\Miniconda3\\lib\\site-packages\\wrapt\\wrappers.py\", line 564, in __call__\r\n    args, kwargs)\r\n  File \"c:\\users\\mih\\code\\datalad\\datalad\\interface\\utils.py\", line 487, in return_func\r\n    results = list(results)\r\n  File \"c:\\users\\mih\\code\\datalad\\datalad\\interface\\utils.py\", line 474, in generator_func\r\n    msg=\"Command did not complete successfully\")\r\ndatalad.support.exceptions.IncompleteResultsError: Command did not complete successfully [{'action': 'add', 'path': 'C:\\\\Users\\\\mih\\\\AppData\\\\Local\\\\Temp\\\\datalad_temp_tree_1m2x5350\\\\ ;abc\u0394\u0419\u05e7\u0645\u0e57\u3042', 'type': 'file', 'refds': 'C:\\\\Users\\\\mih\\\\AppData\\\\Local\\\\Temp\\\\datalad_temp_tree_1m2x5350', 'status': 'error', 'key': None}, {'action': 'add', 'path': 'C:\\\\Users\\\\mih\\\\AppData\\\\Local\\\\Temp\\\\datalad_temp_tree_1m2x5350\\\\dir\\\\ ;abc\u0394\u0419\u05e7\u0645\u0e57\u3042', 'type': 'file', 'refds': 'C:\\\\Users\\\\mih\\\\AppData\\\\Local\\\\Temp\\\\datalad_temp_tree_1m2x5350', 'status': 'error', 'key': None}]\r\n\r\n======================================================================\r\nERROR: datalad.core.local.tests.test_save.test_save_obscure_name\r\n----------------------------------------------------------------------\r\nTraceback (most recent call last):\r\n  File \"C:\\Users\\mih\\Miniconda3\\lib\\site-packages\\nose\\case.py\", line 198, in runTest\r\n    self.test(*self.arg)\r\n  File \"c:\\users\\mih\\code\\datalad\\datalad\\tests\\utils.py\", line 434, in newfunc\r\n    return t(*(arg + (d,)), **kw)\r\n  File \"c:\\users\\mih\\code\\datalad\\datalad\\core\\local\\tests\\test_save.py\", line 744, in test_save_obscure_name\r\n    ds.save(path=fname, result_renderer=\"default\")\r\n  File \"C:\\Users\\mih\\Miniconda3\\lib\\site-packages\\wrapt\\wrappers.py\", line 603, in __call__\r\n    args, kwargs)\r\n  File \"c:\\users\\mih\\code\\datalad\\datalad\\distribution\\dataset.py\", line 526, in apply_func\r\n    return f(**kwargs)\r\n  File \"C:\\Users\\mih\\Miniconda3\\lib\\site-packages\\wrapt\\wrappers.py\", line 564, in __call__\r\n    args, kwargs)\r\n  File \"c:\\users\\mih\\code\\datalad\\datalad\\interface\\utils.py\", line 499, in eval_func\r\n    return return_func(generator_func)(*args, **kwargs)\r\n  File \"C:\\Users\\mih\\Miniconda3\\lib\\site-packages\\wrapt\\wrappers.py\", line 564, in __call__\r\n    args, kwargs)\r\n  File \"c:\\users\\mih\\code\\datalad\\datalad\\interface\\utils.py\", line 487, in return_func\r\n    results = list(results)\r\n  File \"c:\\users\\mih\\code\\datalad\\datalad\\interface\\utils.py\", line 435, in generator_func\r\n    result_renderer, result_xfm, _result_filter, **_kwargs):\r\n  File \"c:\\users\\mih\\code\\datalad\\datalad\\interface\\utils.py\", line 595, in _process_results\r\n    default_result_renderer(res)\r\n  File \"c:\\users\\mih\\code\\datalad\\datalad\\interface\\utils.py\", line 526, in default_result_renderer\r\n    if 'message' in res else ''))\r\n  File \"c:\\users\\mih\\code\\datalad\\datalad\\ui\\dialog.py\", line 75, in message\r\n    self.out.write(msg)\r\n  File \"C:\\Users\\mih\\Miniconda3\\lib\\encodings\\cp1252.py\", line 19, in encode\r\n    return codecs.charmap_encode(input,self.errors,encoding_table)[0]\r\nUnicodeEncodeError: 'charmap' codec can't encode characters in position 17-22: character maps to <undefined>\r\n\r\n======================================================================\r\nERROR: datalad.core.local.tests.test_status.test_status\r\n----------------------------------------------------------------------\r\nTraceback (most recent call last):\r\n  File \"C:\\Users\\mih\\Miniconda3\\lib\\site-packages\\nose\\case.py\", line 198, in runTest\r\n    self.test(*self.arg)\r\n  File \"c:\\users\\mih\\code\\datalad\\datalad\\tests\\utils.py\", line 607, in newfunc\r\n    return t(*(arg + (filename,)), **kw)\r\n  File \"c:\\users\\mih\\code\\datalad\\datalad\\tests\\utils.py\", line 607, in newfunc\r\n    return t(*(arg + (filename,)), **kw)\r\n  File \"c:\\users\\mih\\code\\datalad\\datalad\\core\\local\\tests\\test_status.py\", line 111, in test_status\r\n    ds = get_deeply_nested_structure(text_type(_path))\r\n  File \"c:\\users\\mih\\code\\datalad\\datalad\\tests\\utils.py\", line 1754, in get_deeply_nested_structure\r\n    'annexed_file.txt')\r\n  File \"C:\\Users\\mih\\Miniconda3\\lib\\pathlib.py\", line 1330, in symlink_to\r\n    self._accessor.symlink(target, self, target_is_directory)\r\nOSError: symbolic link privilege not held\r\n\r\n======================================================================\r\nFAIL: datalad.core.local.tests.test_save.test_encoding\r\n----------------------------------------------------------------------\r\nTraceback (most recent call last):\r\n  File \"C:\\Users\\mih\\Miniconda3\\lib\\site-packages\\nose\\case.py\", line 198, in runTest\r\n    self.test(*self.arg)\r\n  File \"c:\\users\\mih\\code\\datalad\\datalad\\tests\\utils.py\", line 434, in newfunc\r\n    return t(*(arg + (d,)), **kw)\r\n  File \"c:\\users\\mih\\code\\datalad\\datalad\\core\\local\\tests\\test_save.py\", line 337, in test_encoding\r\n    assert_repo_status(ds.path, added=[staged], untracked=[untracked])\r\n  File \"c:\\users\\mih\\code\\datalad\\datalad\\tests\\utils.py\", line 1554, in assert_repo_status\r\n    % (state, state_files, oktobefound))\r\nAssertionError: unexpected content of state \"added\": [] != [WindowsPath('C:/Users/mih/AppData/Local/Temp/datalad_temp_tree_6_uf2fjs/ ;abc\u0394\u0419\u05e7\u0645\u0e57\u3042_staged')]\r\n\r\n----------------------------------------------------------------------\r\nRan 70 tests in 562.922s\r\n\r\nFAILED (SKIP=9, errors=8, failures=1)\r\n``` ", "closed_by": {"login": "mih", "id": 136479, "node_id": "MDQ6VXNlcjEzNjQ3OQ==", "avatar_url": "https://avatars.githubusercontent.com/u/136479?v=4", "gravatar_id": "", "url": "https://api.github.com/users/mih", "html_url": "https://github.com/mih", "followers_url": "https://api.github.com/users/mih/followers", "following_url": "https://api.github.com/users/mih/following{/other_user}", "gists_url": "https://api.github.com/users/mih/gists{/gist_id}", "starred_url": "https://api.github.com/users/mih/starred{/owner}{/repo}", "subscriptions_url": "https://api.github.com/users/mih/subscriptions", "organizations_url": "https://api.github.com/users/mih/orgs", "repos_url": "https://api.github.com/users/mih/repos", "events_url": "https://api.github.com/users/mih/events{/privacy}", "received_events_url": "https://api.github.com/users/mih/received_events", "type": "User", "site_admin": false}, "reactions": {"url": "https://api.github.com/repos/datalad/datalad/issues/3633/reactions", "total_count": 0, "+1": 0, "-1": 0, "laugh": 0, "hooray": 0, "confused": 0, "heart": 0, "rocket": 0, "eyes": 0}, "timeline_url": "https://api.github.com/repos/datalad/datalad/issues/3633/timeline", "performed_via_github_app": null}