{"url": "https://api.github.com/repos/datalad/datalad/issues/3775", "repository_url": "https://api.github.com/repos/datalad/datalad", "labels_url": "https://api.github.com/repos/datalad/datalad/issues/3775/labels{/name}", "comments_url": "https://api.github.com/repos/datalad/datalad/issues/3775/comments", "events_url": "https://api.github.com/repos/datalad/datalad/issues/3775/events", "html_url": "https://github.com/datalad/datalad/pull/3775", "id": 506168769, "node_id": "MDExOlB1bGxSZXF1ZXN0MzI3NDUyMDY5", "number": 3775, "title": "ENH: More human readable error on clone failure", "user": {"login": "mih", "id": 136479, "node_id": "MDQ6VXNlcjEzNjQ3OQ==", "avatar_url": "https://avatars.githubusercontent.com/u/136479?v=4", "gravatar_id": "", "url": "https://api.github.com/users/mih", "html_url": "https://github.com/mih", "followers_url": "https://api.github.com/users/mih/followers", "following_url": "https://api.github.com/users/mih/following{/other_user}", "gists_url": "https://api.github.com/users/mih/gists{/gist_id}", "starred_url": "https://api.github.com/users/mih/starred{/owner}{/repo}", "subscriptions_url": "https://api.github.com/users/mih/subscriptions", "organizations_url": "https://api.github.com/users/mih/orgs", "repos_url": "https://api.github.com/users/mih/repos", "events_url": "https://api.github.com/users/mih/events{/privacy}", "received_events_url": "https://api.github.com/users/mih/received_events", "type": "User", "site_admin": false}, "labels": [], "state": "closed", "locked": false, "assignee": null, "assignees": [], "milestone": null, "comments": 2, "created_at": "2019-10-12T10:32:21Z", "updated_at": "2019-10-12T16:36:00Z", "closed_at": "2019-10-12T16:35:57Z", "author_association": "MEMBER", "active_lock_reason": null, "pull_request": {"url": "https://api.github.com/repos/datalad/datalad/pulls/3775", "html_url": "https://github.com/datalad/datalad/pull/3775", "diff_url": "https://github.com/datalad/datalad/pull/3775.diff", "patch_url": "https://github.com/datalad/datalad/pull/3775.patch"}, "body": "A very common reason for such an error is a simple typo in a URL. This change turns:\r\n\r\n```\r\n$ datalad install http://github/datalad/datalad-neuroimaging.git\r\ninstall(error): /tmp/datalad-neuroimaging (dataset) [Failed to clone from any candidate source URL. Encountered errors per each url were: (OrderedDict([('http://github/datalad/datalad-neuroimaging.git', \"Cmd('/usr/lib/git-annex.linux/git') failed due to: exit code(128)\\n  cmdline: /usr/lib/git-annex.linux/git clone --progress -v http://github/datalad/datalad-neuroimaging.git /tmp/datalad-neuroimaging [cmd.py:wait:418]\"), ('http://github/datalad/datalad-neuroimaging.git/.git', \"Cmd('/usr/lib/git-annex.linux/git') failed due to: exit code(128)\\n  cmdline: /usr/lib/git-annex.linux/git clone --progress -v http://github/datalad/datalad-neuroimaging.git/.git /tmp/datalad-neuroimaging [cmd.py:wait:418]\")]),)]\r\n```\r\n\r\nwhich is verbose, but highly redundant and ultimately not very unformative, into\r\n\r\n```\r\n$ datalad install http://github/datalad/datalad-neuroimaging.git\r\ninstall(error): /tmp/datalad-neuroimaging (dataset) [Failed to clone from all attempted sources: ['http://github.com/datalad/datalad-neuroimaging.git', 'http://github.com/datalad/datalad-neuroimaging.git/.git']]\r\n```\r\n\r\nwhich is arguably more likely to help a user realize what was happening and hence fixes gh-3380\r\n\r\nIn case a more informative exception is encountered (has stderr or stdout), the output would be something like:\r\n\r\n```\r\ninstall(error): /tmp/datalad-neuroimaging (dataset) [Failed to clone from any candidate source URL. Encountered errors per each url were:\r\n- http://github.com/datalad/datalad-neuroimaging.git\r\n  Cmd('/usr/lib/git-annex.linux/git') failed due to: exit code(1)\r\n  cmdline: /usr/lib/git-annex.linux/git clone --progress -v http://github.com/datalad/datalad-neuroimaging.git /tmp/datalad-neuroimaging\r\n- http://github.com/datalad/datalad-neuroimaging.git/.git\r\n  Cmd('/usr/lib/git-annex.linux/git') failed due to: exit code(1)\r\n  cmdline: /usr/lib/git-annex.linux/git clone --progress -v http://github.com/datalad/datalad-neuroimaging.git/.git /tmp/datalad-neuroimaging]\r\n```\r\n\r\nalthough I was not able to get `clone` to actually produce such an exception. But it doesn't cost much, so let's keep it in.\r\n\r\nNote that the above output is conditioned upon `datalad.log.result-level=debug`. In the default case, the error is shown twice in identical form, as before and requested by https://github.com/datalad/datalad/issues/3752#issuecomment-538664929 until something better is available.\r\n\r\n@adswa Once this is merged, we can update https://github.com/datalad-handbook/book/blame/master/docs/basics/101-135-help.rst#L169 to the new error message", "closed_by": {"login": "mih", "id": 136479, "node_id": "MDQ6VXNlcjEzNjQ3OQ==", "avatar_url": "https://avatars.githubusercontent.com/u/136479?v=4", "gravatar_id": "", "url": "https://api.github.com/users/mih", "html_url": "https://github.com/mih", "followers_url": "https://api.github.com/users/mih/followers", "following_url": "https://api.github.com/users/mih/following{/other_user}", "gists_url": "https://api.github.com/users/mih/gists{/gist_id}", "starred_url": "https://api.github.com/users/mih/starred{/owner}{/repo}", "subscriptions_url": "https://api.github.com/users/mih/subscriptions", "organizations_url": "https://api.github.com/users/mih/orgs", "repos_url": "https://api.github.com/users/mih/repos", "events_url": "https://api.github.com/users/mih/events{/privacy}", "received_events_url": "https://api.github.com/users/mih/received_events", "type": "User", "site_admin": false}, "reactions": {"url": "https://api.github.com/repos/datalad/datalad/issues/3775/reactions", "total_count": 0, "+1": 0, "-1": 0, "laugh": 0, "hooray": 0, "confused": 0, "heart": 0, "rocket": 0, "eyes": 0}, "timeline_url": "https://api.github.com/repos/datalad/datalad/issues/3775/timeline", "performed_via_github_app": null}